Workbook

Sheet Dim
C3: modelo | D3: Valores
C4: vrp_100 | D4: vrp_100 | E4: vrp_20 | F4: vrp_20 | G4: vrp_50 | H4: vrp_50
A5: Set | B5: name | C5: GAP vrp_100 | D5: duration vrp_100 | E5: GAP vrp_20 | F5: duration vrp_20 | G5: GAP vrp_50 | H5: duration vrp_50 | I5: best gap | J5: total time
A6: A | B6: A-n32-k5 | C6: =Analise_Instancias!L2 -> 0.062524056 | D6: =Analise_Instancias!M2 -> 3.2406287 | E6: =Analise_Instancias!F2 -> 0.01069065 | F6: =Analise_Instancias!G2 -> 2.458679 | G6: =Analise_Instancias!I2 -> 0.061842549 | H6: =Analise_Instancias!J2 -> 3.4842 | I6: =Analise_Instancias!O2 -> 0.01069065 | J6: =Analise_Instancias!Q2 -> 9.1835077
A7: A | B7: A-n33-k5 | C7: =Analise_Instancias!L3 -> 0.10539534 | D7: =Analise_Instancias!M3 -> 3.5166168 | E7: =Analise_Instancias!F3 -> 0.020963776 | F7: =Analise_Instancias!G3 -> 1.9951878 | G7: =Analise_Instancias!I3 -> 0.019843443 | H7: =Analise_Instancias!J3 -> 3.653559 | I7: =Analise_Instancias!O3 -> 0.019843443 | J7: =Analise_Instancias!Q3 -> 9.1653636
A8: A | B8: A-n33-k6 | C8: =Analise_Instancias!L4 -> 0.047760832 | D8: =Analise_Instancias!M4 -> 3.5166168 | E8: =Analise_Instancias!F4 -> 0.027729456 | F8: =Analise_Instancias!G4 -> 1.9951878 | G8: =Analise_Instancias!I4 -> 0.0034561363 | H8: =Analise_Instancias!J4 -> 3.653559 | I8: =Analise_Instancias!O4 -> 0.0034561363 | J8: =Analise_Instancias!Q4 -> 9.1653636
A9: A | B9: A-n34-k5 | C9: =Analise_Instancias!L5 -> 0.012121362 | D9: =Analise_Instancias!M5 -> 3.6198652 | E9: =Analise_Instancias!F5 -> 0.031864902 | F9: =Analise_Instancias!G5 -> 1.9882326 | G9: =Analise_Instancias!I5 -> 0.015708158 | H9: =Analise_Instancias!J5 -> 3.712981 | I9: =Analise_Instancias!O5 -> 0.012121362 | J9: =Analise_Instancias!Q5 -> 9.3210788
A10: A | B10: A-n36-k5 | C10: =Analise_Instancias!L6 -> 0.013855821 | D10: =Analise_Instancias!M6 -> 3.7884512 | E10: =Analise_Instancias!F6 -> 0.02771103 | F10: =Analise_Instancias!G6 -> 2.277431 | G10: =Analise_Instancias!I6 -> 0.087094189 | H10: =Analise_Instancias!J6 -> 3.8794634 | I10: =Analise_Instancias!O6 -> 0.013855821 | J10: =Analise_Instancias!Q6 -> 9.9453456
A11: A | B11: A-n37-k5 | C11: =Analise_Instancias!L7 -> 0.10664621 | D11: =Analise_Instancias!M7 -> 3.6620553 | E11: =Analise_Instancias!F7 -> 0.042508204 | F11: =Analise_Instancias!G7 -> 4.4269788 | G11: =Analise_Instancias!I7 -> 0.044779551 | H11: =Analise_Instancias!J7 -> 3.9273241 | I11: =Analise_Instancias!O7 -> 0.042508204 | J11: =Analise_Instancias!Q7 -> 12.016358
A12: A | B12: A-n37-k6 | C12: =Analise_Instancias!L8 -> 0.0081600595 | D12: =Analise_Instancias!M8 -> 3.6620553 | E12: =Analise_Instancias!F8 -> 0.03449882 | F12: =Analise_Instancias!G8 -> 4.4269788 | G12: =Analise_Instancias!I8 -> 0.0084613121 | H12: =Analise_Instancias!J8 -> 3.9273241 | I12: =Analise_Instancias!O8 -> 0.0081600595 | J12: =Analise_Instancias!Q8 -> 12.016358
A13: A | B13: A-n38-k5 | C13: =Analise_Instancias!L9 -> 0.036940985 | D13: =Analise_Instancias!M9 -> 3.7448993 | E13: =Analise_Instancias!F9 -> 0.01318836 | F13: =Analise_Instancias!G9 -> 4.0925169 | G13: =Analise_Instancias!I9 -> 0.05972683 | H13: =Analise_Instancias!J9 -> 3.6349518 | I13: =Analise_Instancias!O9 -> 0.01318836 | J13: =Analise_Instancias!Q9 -> 11.472368
A14: A | B14: A-n39-k5 | C14: =Analise_Instancias!L10 -> 0.039604688 | D14: =Analise_Instancias!M10 -> 3.7533278 | E14: =Analise_Instancias!F10 -> 0.021533901 | F14: =Analise_Instancias!G10 -> 3.0453658 | G14: =Analise_Instancias!I10 -> 0.013887206 | H14: =Analise_Instancias!J10 -> 0.19466853 | I14: =Analise_Instancias!O10 -> 0.013887206 | J14: =Analise_Instancias!Q10 -> 6.9933622
A15: A | B15: A-n39-k6 | C15: =Analise_Instancias!L11 -> 0.056693067 | D15: =Analise_Instancias!M11 -> 3.7533278 | E15: =Analise_Instancias!F11 -> 0.0066954318 | F15: =Analise_Instancias!G11 -> 3.0453658 | G15: =Analise_Instancias!I11 -> 0.0051539819 | H15: =Analise_Instancias!J11 -> 0.19466853 | I15: =Analise_Instancias!O11 -> 0.0051539819 | J15: =Analise_Instancias!Q11 -> 6.9933622
A16: A | B16: A-n44-k6 | C16: =Analise_Instancias!L12 -> 0.031212415 | D16: =Analise_Instancias!M12 -> 3.646445 | E16: =Analise_Instancias!F12 -> 0.023767754 | F16: =Analise_Instancias!G12 -> 2.4535391 | G16: =Analise_Instancias!I12 -> 0.020404502 | H16: =Analise_Instancias!J12 -> 4.325841 | I16: =Analise_Instancias!O12 -> 0.020404502 | J16: =Analise_Instancias!Q12 -> 10.425825
A17: A | B17: A-n45-k6 | C17: =Analise_Instancias!L13 -> 0.05324451 | D17: =Analise_Instancias!M13 -> 3.7981927 | E17: =Analise_Instancias!F13 -> 0.051153215 | F17: =Analise_Instancias!G13 -> 2.617625 | G17: =Analise_Instancias!I13 -> 0.050454027 | H17: =Analise_Instancias!J13 -> 4.8942862 | I17: =Analise_Instancias!O13 -> 0.050454027 | J17: =Analise_Instancias!Q13 -> 11.310104
... A211: X | B211: X-n979-k58 | C211: =Analise_Instancias!L207 -> 0.089035683 | D211: =Analise_Instancias!M207 -> 7.2582247 | E211: =Analise_Instancias!F207 -> 0.38564159 | F211: =Analise_Instancias!G207 -> 11.609019 | G211: =Analise_Instancias!I207 -> 0.11834569 | H211: =Analise_Instancias!J207 -> 7.4955378 | I211: =Analise_Instancias!O207 -> 0.089035683 | J211: =Analise_Instancias!Q207 -> 26.362781

Sheet Consolidado
D1: Gap com BKS
A2: Set | B2: qty instances | C2: dimension | D2: capacity | E2: Tempo Médio por instância (s) | F2: Média | G2: Desvio | H2: Mín | I2: Q1 | J2: Q2 | K2: Q3 | L2: Máx
A3: A | B3: =Analise_Sets!B2 -> 27 | C3: 32 - 80 | D3: 100 | E3: =Analise_Sets!O2 -> 11.292922 | F3: =Analise_Sets!C2 -> 0.01969888 | G3: =Analise_Sets!D2 -> 0.012653279 | H3: =Analise_Sets!E2 -> 0.0034561363 | I3: =Analise_Sets!F2 -> 0.011750388 | J3: =Analise_Sets!G2 -> 0.015008983 | K3: =Analise_Sets!H2 -> 0.023399458 | L3: =Analise_Sets!I2 -> 0.050454027
A4: B | B4: =Analise_Sets!B3 -> 23 | C4: 30-77 | D4: 100 | E4: =Analise_Sets!O3 -> 11.885841 | F4: =Analise_Sets!C3 -> 0.024573061 | G4: =Analise_Sets!D3 -> 0.015822579 | H4: =Analise_Sets!E3 -> 0 | I4: =Analise_Sets!F3 -> 0.015492651 | J4: =Analise_Sets!G3 -> 0.022957774 | K4: =Analise_Sets!H3 -> 0.033337966 | L4: =Analise_Sets!I3 -> 0.064526043
A5: E | B5: =Analise_Sets!B4 -> 11 | C5: 13-101 | D5: 100 - 8000 | E5: =Analise_Sets!O4 -> 19.385841 | F5: =Analise_Sets!C4 -> 0.020385737 | G5: =Analise_Sets!D4 -> 0.017565842 | H5: =Analise_Sets!E4 -> 0 | I5: =Analise_Sets!F4 -> 0.0044643484 | J5: =Analise_Sets!G4 -> 0.019138466 | K5: =Analise_Sets!H4 -> 0.035754711 | L5: =Analise_Sets!I4 -> 0.045604531
A6: F | B6: =Analise_Sets!B5 -> 3 | C6: 45 - 135 | D6: 2010 - 30000 | E6: =Analise_Sets!O5 -> 19.976678 | F6: =Analise_Sets!C5 -> 0.073723506 | G6: =Analise_Sets!D5 -> 0.06835482 | H6: =Analise_Sets!E5 -> 0.0051744998 | I6: =Analise_Sets!F5 -> 0.039644024 | J6: =Analise_Sets!G5 -> 0.074113548 | K6: =Analise_Sets!H5 -> 0.10799801 | L6: =Analise_Sets!I5 -> 0.14188247
A7: M | B7: =Analise_Sets!B6 -> 5 | C7: 101-200 | D7: 200 | E7: =Analise_Sets!O6 -> 12.215057 | F7: =Analise_Sets!C6 -> 0.051418655 | G7: =Analise_Sets!D6 -> 0.023391578 | H7: =Analise_Sets!E6 -> 0.01414713 | I7: =Analise_Sets!F6 -> 0.042398538 | J7: =Analise_Sets!G6 -> 0.066024044 | K7: =Analise_Sets!H6 -> 0.0660769 | L7: =Analise_Sets!I6 -> 0.068446664
A8: P | B8: =Analise_Sets!B7 -> 24 | C8: 16 - 101 | D8: 35 - 3000 | E8: =Analise_Sets!O7 -> 14.499928 | F8: =Analise_Sets!C7 -> 0.023712541 | G8: =Analise_Sets!D7 -> 0.019470975 | H8: =Analise_Sets!E7 -> 0 | I8: =Analise_Sets!F7 -> 0.0085358097 | J8: =Analise_Sets!G7 -> 0.02256966 | K8: =Analise_Sets!H7 -> 0.030699868 | L8: =Analise_Sets!I7 -> 0.078291946
A9: Taillard | B9: =Analise_Sets!B8 -> 13 | C9: 76 - 386 | D9: 65 - 2043 | E9: =Analise_Sets!O8 -> 19.637472 | F9: =Analise_Sets!C8 -> 0.069056399 | G9: =Analise_Sets!D8 -> 0.024427951 | H9: =Analise_Sets!E8 -> 0.040010494 | I9: =Analise_Sets!F8 -> 0.061838101 | J9: =Analise_Sets!G8 -> 0.067534397 | K9: =Analise_Sets!H8 -> 0.068383309 | L9: =Analise_Sets!I8 -> 0.13418335
A10: X | B10: =Analise_Sets!B9 -> 100 | C10: 101 - 1001 | D10: 3 - 1816 | E10: =Analise_Sets!O9 -> 13.027292 | F10: =Analise_Sets!C9 -> 0.09939418 | G10: =Analise_Sets!D9 -> 0.044483976 | H10: =Analise_Sets!E9 -> 0.023559804 | I10: =Analise_Sets!F9 -> 0.065771706 | J10: =Analise_Sets!G9 -> 0.093025962 | K10: =Analise_Sets!H9 -> 0.1243822 | L10: =Analise_Sets!I9 -> 0.25213419
A13: Set | B13: A | I13: Set | J13: B | Q13: Set | R13: E | Y13: Set | Z13: F | AG13: Set | AH13: M | AO13: Set | AP13: P | AW13: Set | AX13: Taillard | BE13: Set | BF13: X
A14: qnt | B14: 27 | I14: qnt | J14: 23 | Q14: qnt | R14: 11 | Y14: qnt | Z14: 3 | AG14: qnt | AH14: 5 | AO14: qnt | AP14: 24 | AW14: qnt | AX14: 13 | BE14: qnt | BF14: 100
A15: Linha | B15: 6 | I15: Linha | J15: 33 | Q15: Linha | R15: 56 | Y15: Linha | Z15: 67 | AG15: Linha | AH15: 102 | AO15: Linha | AP15: 107 | AW15: Linha | AX15: 131 | BE15: Linha | BF15: 144
A17: Média | B17: Desvio | C17: Mín | D17: Q1 | E17: Q2 | F17: Q3 | G17: Máx | I17: Média | J17: Desvio | K17: Mín | L17: Q1 | M17: Q2 | N17: Q3 | O17: Máx | Q17: Média | R17: Desvio | S17: Mín | T17: Q1 | U17: Q2 | V17: Q3 | W17: Máx | Y17: Média | Z17: Desvio | AA17: Mín | AB17: Q1 | AC17: Q2 | AD17: Q3 | AE17: Máx | AG17: Média | AH17: Desvio | AI17: Mín | AJ17: Q1 | AK17: Q2 | AL17: Q3 | AM17: Máx | AO17: Média | AP17: Desvio | AQ17: Mín | AR17: Q1 | AS17: Q2 | AT17: Q3 | AU17: Máx | AW17: Média | AX17: Desvio | AY17: Mín | AZ17: Q1 | BA17: Q2 | BB17: Q3 | BC17: Máx | BE17: Média | BF17: Desvio | BG17: Mín | BH17: Q1 | BI17: Q2 | BJ17: Q3 | BK17: Máx
A18: 0.01969888 | B18: 0.012416748 | C18: 0.0034561363 | D18: 0.011750388 | E18: 0.015008983 | F18: 0.023399458 | G18: 0.050454027 | I18: 0.024379942 | J18: 0.015804448 | K18: -0.004441727 | L18: 0.015492651 | M18: 0.022957774 | N18: 0.033337966 | O18: 0.064526043 | Q18: 0.015712531 | R18: 0.026256999 | S18: -0.05140526 | T18: 0.0044643484 | U18: 0.019138466 | V18: 0.035754711 | W18: 0.045604531 | Y18: 0.073723506 | Z18: 0.055811477 | AA18: 0.0051744998 | AB18: 0.039644024 | AC18: 0.074113548 | AD18: 0.10799801 | AE18: 0.14188247 | AG18: 0.051418655 | AH18: 0.020922063 | AI18: 0.01414713 | AJ18: 0.042398538 | AK18: 0.066024044 | AL18: 0.0660769 | AM18: 0.068446664 | AO18: 0.021540291 | AP18: 0.022776537 | AQ18: -0.028574327 | AR18: 0.0085358097 | AS18: 0.02256966 | AT18: 0.030699868 | AU18: 0.078291946 | AW18: 0.069056399 | AX18: 0.023469616 | AY18: 0.040010494 | AZ18: 0.061838101 | BA18: 0.067534397 | BB18: 0.068383309 | BC18: 0.13418335 | BE18: 0.09939418 | BF18: 0.044260997 | BG18: 0.023559804 | BH18: 0.065771706 | BI18: 0.093025962 | BJ18: 0.1243822 | BK18: 0.25213419
A20: Gaps set A | B20: Duration | I20: Gaps set B | J20: Duration | Q20: Gaps set E | R20: Duration | Y20: Gaps set F | Z20: Duration | AG20: Gaps set M | AH20: Duration | AO20: Gaps set P | AP20: Duration | AW20: Gaps set Taillard | AX20: Duration | BE20: Gaps set X | BF20: Duration
A21: 0.01069065 | B21: 9.1835077 | I21: 0.037612552 | J21: 9.9596844 | Q21: 0.045604531 | R21: 20.368714 | Y21: 0.14188247 | Z21: 33.907054 | AG21: 0.01414713 | AH21: 8.0180914 | AO21: 0.066753191 | AP21: 8.4147637 | AW21: 0.067959099 | AX21: 16.942796 | BE21: 0.12437429 | BF21: 17.911424
A22: 0.019843443 | B22: 9.1653636 | I22: 0.0087469266 | J22: 9.7051272 | Q22: 0.038253691 | R22: 20.368714 | Y22: 0.0051744998 | Z22: 11.620859 | AG22: 0.042398538 | AH22: 7.9028399 | AO22: 0.00432685 | AP22: 5.4356191 | AW22: 0.040010494 | AX22: 16.942796 | BE22: 0.051820779 | BF22: 5.6703146
A23: 0.0034561363 | B23: 9.1653636 | I23: 0.016940931 | J23: 9.8264017 | Q23: 0.00074609375 | R23: 9.6456866 | Y23: 0.074113548 | Z23: 14.402122 | AG23: 0.066024044 | AH23: 10.644611 | AO23: 0.040769469 | AP23: 13.71206 | AW23: 0.071103448 | AX23: 16.942796 | BE23: 0.046717043 | BF23: 7.3362346
A24: 0.012121362 | B24: 9.3210788 | I24: 0.016213894 | J24: 9.8898654 | Q24: 0.0015546266 | R24: 5.9792466 | AG24: 0.068446664 | AH24: 17.254871 | AO24: 0.021394094 | AP24: 14.04752 | AW24: 0.062999505 | AX24: 16.942796 | BE24: 0.030600111 | BF24: 7.6943383
A25: 0.013855821 | B25: 9.9453456 | I25: 0.028609034 | J25: 10.283905 | Q25: -0.05140526 | R25: 4.5576293 | AG25: 0.0660769 | AH25: 17.254871 | AO25: 0.0081116012 | AP25: 10.827728 | AW25: 0.068383309 | AX25: 27.142814 | BE25: 0.039238706 | BF25: 8.2404594
A26: 0.042508204 | B26: 12.016358 | I26: 0.023203814 | J26: 10.636882 | Q26: 0.0073740702 | R26: 11.987454 | AO26: 0.0094944989 | AP26: 10.823854 | AW26: 0.04681505 | AX26: 27.142814 | BE26: 0.054362565 | BF26: 9.1661818
A27: 0.0081600595 | B27: 12.016358 | I27: 0.0094216236 | J27: 13.075326 | Q27: 0.0075371975 | R27: 11.270206 | AO27: -0.023559672 | AP27: 10.823854 | AW27: 0.098197457 | AX27: 27.142814 | BE27: 0.057359046 | BF27: 8.839474
A28: 0.01318836 | B28: 11.472368 | I28: 0.027218792 | J28: 11.093324 | Q28: 0.03202522 | R28: 32.26665 | AO28: 0.018617107 | AP28: 11.126914 | AW28: 0.066679101 | AX28: 27.142814 | BE28: 0.04268388 | BF28: 8.5046582
A29: 0.013887206 | B29: 6.9933622 | I29: 0.019928751 | J29: 11.260767 | Q29: 0.033255731 | R29: 32.26665 | AO29: 0.0081357998 | AP29: 14.461716 | AW29: 0.13418335 | AX29: 25.904552 | BE29: 0.13649617 | BF29: 8.358731
A30: 0.0051539819 | B30: 6.9933622 | I30: 0.064526043 | J30: 11.260767 | Q30: 0.038753476 | R30: 32.26665 | AO30: 0.0086691464 | AP30: 13.977951 | AW30: 0.043996851 | AX30: 13.260037 | BE30: 0.023559804 | BF30: 8.2392976
A31: 0.020404502 | B31: 10.425825 | I31: 0.018979133 | J31: 11.313071 | Q31: 0.019138466 | R31: 32.26665 | AO31: 0.039602433 | AP31: 20.962139 | AW31: 0.067534397 | AX31: 13.260037 | BE31: 0.067580737 | BF31: 8.3479524
A32: 0.050454027 | B32: 11.310104 | I32: 0.0056232359 | J32: 11.313071 | AO32: 0.018016388 | AP32: 20.962139 | AW32: 0.06803302 | AX32: 13.260037 | BE32: 0.064084869 | BF32: 9.4408457
A33: 0.011784898 | B33: 11.310104 | I33: -0.004441727 | J33: 11.532375 | AO33: 0.018235873 | AP33: 20.962139 | AW33: 0.061838101 | AX33: 13.260037 | BE33: 0.12651758 | BF33: 8.9983783
A34: 0.011715879 | B34: 13.134425 | I34: 0.014771407 | J34: 11.422984 | AO34: 0.033125616 | AP34: 12.330393 | BE34: 0.040644119 | BF34: 9.4030943
A35: 0.0084231929 | B35: 10.902099 | I35: 0.040261103 | J35: 12.893541 | AO35: 0.023745226 | AP35: 21.68264 | BE35: 0.046728011 | BF35: 9.8404741
A36: 0.013595309 | B36: 11.365095 | I36: 0.001451398 | J36: 18.971728 | AO36: -0.028574327 | AP36: 21.68264 | BE36: 0.034353984 | BF36: 9.6883397
A37: 0.0054127253 | B37: 11.208788 | I37: 0.022957774 | J37: 18.971728 | AO37: 0.033870966 | AP37: 21.68264 | BE37: 0.057570829 | BF37: 9.7494955
A38: 0.018314529 | B38: 12.427639 | I38: 0.043290164 | J38: 11.509818 | AO38: 0.00034378986 | AP38: 21.68264 | BE38: 0.087713254 | BF38: 9.4971671
A39: 0.018867707 | B39: 11.176435 | I39: 0.050256816 | J39: 11.23395 | AO39: 0.023817329 | AP39: 15.426572 | BE39: 0.044506333 | BF39: 9.9701931
A40: 0.038405162 | B40: 11.40924 | I40: 0.022122369 | J40: 10.923312 | AO40: 0.027607437 | AP40: 15.426572 | BE40: 0.047046652 | BF40: 9.8055694
A41: 0.031584746 | B41: 10.341265 | I41: 0.02906338 | J41: 15.286508 | AO41: 0.026438549 | AP41: 10.831694 | BE41: 0.090321334 | BF41: 9.2868125
A42: 0.022325211 | B42: 19.159808 | I42: 0.026211241 | J42: 10.334749 | AO42: 0.029891285 | AP42: 10.169125 | BE42: 0.071715217 | BF42: 10.263689
A43: 0.015008983 | B43: 19.159808 | I43: 0.037770014 | J43: 10.67547 | AO43: 0.078291946 | AP43: 10.272475 | BE43: 0.055875219 | BF43: 10.101443
A44: 0.024218541 | B44: 10.904805 | AO44: 0.029842395 | AP44: 10.272475 | BE44: 0.061696588 | BF44: 8.9607823
...

Sheet Data
A1: ID | B1: cost_ai | C1: tours | D1: durations | E1: Set | F1: instance | G1: name | H1: modelo | I1: cte | J1: REF COST | K1: C1 | L1: C2 | M1: C3 | N1: GAP
A2: 0 | B2: 833.01886 | C2: [0, 20, 5, 25, 10, 15, 29, 27, 0, 21, 31, 19, 17, 13, 7, 26, 0, 22, 9, 8, 11, 4, 28, 18, 24, 0, 14, 23, 2, 3, 6, 0, 30, 16, 1, 12, 0] | D2: 3.2406287 | E2: A | F2: A_n31 | G2: A-n32-k5 | H2: vrp_100 | I2: 1 | J2: 784 | K2: 784 | L2: 0 | M2: 0 | N2: =IFERROR(B2/J2-1,"") -> 0.062524056 | P2: 1 | Q2: 0 | R2: 0 | T2: A-n32-k5
A3: 1 | B3: 792.38147 | C3: [0, 12, 1, 16, 30, 0, 21, 31, 19, 17, 13, 7, 26, 0, 6, 3, 2, 23, 4, 11, 28, 14, 0, 20, 5, 29, 25, 10, 15, 22, 9, 8, 18, 0, 24, 27, 0] | D3: 2.458679 | E3: A | F3: A_n31 | G3: A-n32-k5 | H3: vrp_20 | I3: 1 | J3: 784 | K3: 0 | L3: 0 | M3: 784 | N3: =IFERROR(B3/J3-1,"") -> 0.01069065 | P3: 0 | Q3: 0 | R3: 1 | V3: A-n32-k5
A4: 2 | B4: 832.48456 | C4: [0, 20, 5, 25, 10, 15, 29, 27, 0, 3, 23, 28, 4, 11, 8, 18, 9, 22, 14, 0, 6, 2, 17, 19, 31, 21, 26, 0, 12, 1, 13, 7, 16, 0, 24, 30, 0] | D4: 3.4842 | E4: A | F4: A_n31 | G4: A-n32-k5 | H4: vrp_50 | I4: 1 | J4: 784 | K4: 0 | L4: 784 | M4: 0 | N4: =IFERROR(B4/J4-1,"") -> 0.061842549 | P4: 0 | Q4: 1 | R4: 0 | U4: A-n32-k5
A5: 3 | B5: 730.66632 | C5: [0, 11, 19, 14, 21, 1, 31, 18, 28, 0, 2, 24, 6, 0, 23, 29, 3, 16, 15, 22, 0, 32, 13, 8, 7, 26, 5, 27, 12, 0, 9, 17, 10, 30, 25, 0, 20, 4, 0] | D5: 3.5166168 | E5: A | F5: A_n32 | G5: A-n33-k5 | H5: vrp_100 | I5: 2 | J5: 661 | K5: 661 | L5: 0 | M5: 0 | N5: =IFERROR(B5/J5-1,"") -> 0.10539534 | P5: 2 | Q5: 0 | R5: 0 | T5: A-n33-k5
A6: 4 | B6: 777.43854 | C6: [0, 7, 2, 15, 9, 20, 19, 6, 0, 22, 26, 4, 8, 3, 5, 0, 13, 18, 1, 14, 0, 17, 29, 11, 32, 0, 10, 12, 21, 0, 25, 16, 30, 27, 31, 23, 24, 0, 28, 0] | D6: 3.5166168 | E6: A | F6: A_n32 | G6: A-n33-k6 | H6: vrp_100 | I6: 2 | J6: 742 | K6: 742 | L6: 0 | M6: 0 | N6: =IFERROR(B6/J6-1,"") -> 0.047760832 | P6: 2 | Q6: 0 | R6: 0 | T6: A-n33-k6
A7: 5 | B7: 674.85706 | C7: [0, 24, 6, 19, 14, 21, 1, 31, 11, 0, 29, 16, 3, 9, 17, 10, 0, 4, 12, 27, 25, 30, 15, 0, 20, 5, 26, 7, 8, 13, 32, 2, 0, 23, 18, 28, 22, 0] | D7: 1.9951878 | E7: A | F7: A_n32 | G7: A-n33-k5 | H7: vrp_20 | I7: 2 | J7: 661 | K7: 0 | L7: 0 | M7: 661 | N7: =IFERROR(B7/J7-1,"") -> 0.020963776 | P7: 0 | Q7: 0 | R7: 2 | V7: A-n33-k5
A8: 6 | B8: 762.57526 | C8: [0, 21, 25, 16, 30, 27, 28, 0, 10, 12, 32, 0, 17, 11, 29, 19, 18, 0, 5, 8, 3, 2, 15, 9, 20, 7, 0, 14, 1, 6, 13, 0, 22, 4, 26, 24, 23, 31, 0] | D8: 1.9951878 | E8: A | F8: A_n32 | G8: A-n33-k6 | H8: vrp_20 | I8: 2 | J8: 742 | K8: 0 | L8: 0 | M8: 742 | N8: =IFERROR(B8/J8-1,"") -> 0.027729456 | P8: 0 | Q8: 0 | R8: 2 | V8: A-n33-k6
A9: 7 | B9: 674.11652 | C9: [0, 24, 6, 19, 14, 21, 1, 31, 11, 0, 2, 32, 13, 8, 7, 26, 20, 0, 4, 5, 27, 25, 30, 12, 0, 10, 17, 9, 3, 16, 29, 0, 22, 15, 28, 18, 23, 0] | D9: 3.653559 | E9: A | F9: A_n32 | G9: A-n33-k5 | H9: vrp_50 | I9: 2 | J9: 661 | K9: 0 | L9: 661 | M9: 0 | N9: =IFERROR(B9/J9-1,"") -> 0.019843443 | P9: 0 | Q9: 2 | R9: 0 | U9: A-n33-k5
A10: 8 | B10: 744.56445 | C10: [0, 14, 17, 29, 11, 10, 32, 0, 21, 12, 0, 19, 20, 9, 15, 2, 3, 8, 0, 1, 18, 6, 7, 13, 0, 25, 16, 30, 27, 28, 0, 5, 4, 26, 22, 24, 23, 31, 0] | D10: 3.653559 | E10: A | F10: A_n32 | G10: A-n33-k6 | H10: vrp_50 | I10: 2 | J10: 742 | K10: 0 | L10: 742 | M10: 0 | N10: =IFERROR(B10/J10-1,"") -> 0.0034561363 | P10: 0 | Q10: 2 | R10: 0 | U10: A-n33-k6
A11: 9 | B11: 787.43042 | C11: [0, 5, 30, 24, 27, 1, 29, 0, 23, 11, 8, 15, 6, 14, 0, 10, 13, 28, 31, 25, 17, 19, 7, 0, 21, 32, 3, 12, 9, 22, 2, 18, 0, 26, 4, 33, 16, 20, 0] | D11: 3.6198652 | E11: A | F11: A_n33 | G11: A-n34-k5 | H11: vrp_100 | I11: 1 | J11: 778 | K11: 778 | L11: 0 | M11: 0 | N11: =IFERROR(B11/J11-1,"") -> 0.012121362 | P11: 1 | Q11: 0 | R11: 0 | T11: A-n34-k5
A12: 10 | B12: 802.79089 | C12: [0, 20, 33, 16, 22, 3, 12, 9, 2, 0, 18, 21, 32, 28, 31, 25, 17, 0, 7, 1, 27, 23, 11, 19, 13, 10, 0, 6, 15, 8, 29, 14, 0, 24, 30, 5, 26, 4, 0] | D12: 1.9882326 | E12: A | F12: A_n33 | G12: A-n34-k5 | H12: vrp_20 | I12: 1 | J12: 778 | K12: 0 | L12: 0 | M12: 778 | N12: =IFERROR(B12/J12-1,"") -> 0.031864902 | P12: 0 | Q12: 0 | R12: 1 | V12: A-n34-k5
A13: 11 | B13: 790.22095 | C13: [0, 21, 32, 28, 31, 25, 13, 10, 0, 17, 19, 11, 23, 27, 1, 29, 0, 7, 6, 15, 8, 14, 0, 18, 2, 9, 12, 3, 22, 16, 33, 0, 24, 30, 5, 0, 20, 4, 26, 0] | D13: 3.712981 | E13: A | F13: A_n33 | G13: A-n34-k5 | H13: vrp_50 | I13: 1 | J13: 778 | K13: 0 | L13: 778 | M13: 0 | N13: =IFERROR(B13/J13-1,"") -> 0.015708158 | P13: 0 | Q13: 1 | R13: 0 | U13: A-n34-k5
A14: 12 | B14: 810.0708 | C14: [0, 12, 31, 19, 4, 3, 6, 9, 0, 28, 14, 34, 23, 2, 35, 8, 15, 0, 21, 18, 33, 29, 30, 17, 13, 32, 22, 1, 0, 25, 27, 24, 11, 16, 0, 5, 20, 26, 7, 10, 0] | D14: 3.7884512 | E14: A | F14: A_n35 | G14: A-n36-k5 | H14: vrp_100 | I14: 1 | J14: 799 | K14: 799 | L14: 0 | M14: 0 | N14: =IFERROR(B14/J14-1,"") -> 0.013855821 | P14: 1 | Q14: 0 | R14: 0 | T14: A-n36-k5
A15: 13 | B15: 821.14111 | C15: [0, 16, 1, 22, 13, 17, 30, 32, 18, 21, 24, 0, 11, 27, 33, 29, 31, 19, 4, 3, 6, 23, 0, 25, 12, 28, 9, 5, 0, 20, 14, 34, 2, 35, 8, 15, 0, 26, 7, 10, 0] | D15: 2.277431 | E15: A | F15: A_n35 | G15: A-n36-k5 | H15: vrp_20 | I15: 1 | J15: 799 | K15: 0 | L15: 0 | M15: 799 | N15: =IFERROR(B15/J15-1,"") -> 0.02771103 | P15: 0 | Q15: 0 | R15: 1 | V15: A-n36-k5
A16: 14 | B16: 868.58826 | C16: [0, 16, 1, 22, 32, 13, 17, 30, 29, 33, 18, 27, 0, 11, 24, 21, 25, 5, 0, 12, 31, 19, 4, 3, 6, 28, 0, 9, 14, 34, 23, 2, 35, 8, 0, 26, 20, 15, 7, 10, 0] | D16: 3.8794634 | E16: A | F16: A_n35 | G16: A-n36-k5 | H16: vrp_50 | I16: 1 | J16: 799 | K16: 0 | L16: 799 | M16: 0 | N16: =IFERROR(B16/J16-1,"") -> 0.087094189 | P16: 0 | Q16: 1 | R16: 0 | U16: A-n36-k5
A17: 15 | B17: 740.34631 | C17: [0, 21, 1, 17, 14, 23, 24, 9, 11, 27, 8, 3, 0, 15, 34, 32, 28, 31, 26, 30, 18, 35, 25, 0, 20, 19, 2, 12, 0, 16, 22, 13, 33, 5, 6, 10, 0, 36, 29, 4, 7, 0] | D17: 3.6620553 | E17: A | F17: A_n36 | G17: A-n37-k5 | H17: vrp_100 | I17: 2 | J17: 669 | K17: 669 | L17: 0 | M17: 0 | N17: =IFERROR(B17/J17-1,"") -> 0.10664621 | P17: 2 | Q17: 0 | R17: 0 | T17: A-n37-k5
A18: 16 | B18: 956.7439 | C18: [0, 16, 35, 25, 7, 0, 27, 32, 15, 30, 13, 0, 10, 11, 12, 22, 23, 28, 2, 33, 1, 20, 0, 4, 26, 21, 9, 19, 31, 0, 18, 17, 34, 3, 5, 8, 0, 24, 29, 36, 6, 14, 0] | D18: 3.6620553 | E18: A | F18: A_n36 | G18: A-n37-k6 | H18: vrp_100 | I18: 2 | J18: 949 | K18: 949 | L18: 0 | M18: 0 | N18: =IFERROR(B18/J18-1,"") -> 0.0081600595 | P18: 2 | Q18: 0 | R18: 0 | T18: A-n37-k6
A19: 17 | B19: 697.43799 | C19: [0, 15, 34, 26, 35, 18, 31, 28, 32, 29, 36, 0, 3, 24, 9, 11, 27, 8, 25, 30, 0, 17, 14, 23, 20, 19, 2, 10, 6, 5, 33, 0, 1, 12, 13, 22, 7, 4, 0, 21, 16, 0] | D19: 4.4269788 | E19: A | F19: A_n36 | G19: A-n37-k5 | H19: vrp_20 | I19: 2 | J19: 669 | K19: 0 | L19: 0 | M19: 669 | N19: =IFERROR(B19/J19-1,"") -> 0.042508204 | P19: 0 | Q19: 0 | R19: 2 | V19: A-n37-k5
A20: 18 | B20: 981.73938 | C20: [0, 20, 8, 5, 3, 1, 31, 34, 0, 6, 33, 2, 28, 9, 19, 17, 4, 0, 26, 10, 11, 12, 22, 23, 21, 0, 32, 15, 30, 13, 18, 0, 7, 25, 35, 27, 0, 24, 16, 14, 36, 29, 0] | D20: 4.4269788 | E20: A | F20: A_n36 | G20: A-n37-k6 | H20: vrp_20 | I20: 2 | J20: 949 | K20: 0 | L20: 0 | M20: 949 | N20: =IFERROR(B20/J20-1,"") -> 0.03449882 | P20: 0 | Q20: 0 | R20: 2 | V20: A-n37-k6
A21: 19 | B21: 698.95752 | C21: [0, 15, 30, 25, 35, 18, 26, 31, 28, 32, 29, 0, 34, 36, 0, 3, 8, 27, 11, 9, 24, 23, 20, 19, 2, 14, 0, 17, 12, 10, 6, 5, 33, 4, 7, 0, 21, 16, 22, 13, 1, 0] | D21: 3.9273241 | E21: A | F21: A_n36 | G21: A-n37-k5 | H21: vrp_50 | I21: 2 | J21: 669 | K21: 0 | L21: 669 | M21: 0 | N21: =IFERROR(B21/J21-1,"") -> 0.044779551 | P21: 0 | Q21: 2 | R21: 0 | U21: A-n37-k5
A22: 20 | B22: 957.02979 | C22: [0, 4, 12, 22, 23, 28, 2, 21, 9, 33, 0, 26, 10, 11, 30, 15, 0, 18, 17, 34, 31, 19, 13, 0, 25, 35, 32, 27, 0, 6, 8, 5, 3, 1, 20, 14, 0, 7, 16, 24, 29, 36, 0] | D22: 3.9273241 | E22: A | F22: A_n36 | G22: A-n37-k6 | H22: vrp_50 | I22: 2 | J22: 949 | K22: 0 | L22: 949 | M22: 0 | N22: =IFERROR(B22/J22-1,"") -> 0.0084613121 | P22: 0 | Q22: 2 | R22: 0 | U22: A-n37-k6
A23: 21 | B23: 756.96692 | C23: [0, 24, 2, 15, 13, 36, 17, 9, 0, 14, 0, 8, 33, 35, 23, 26, 30, 0, 21, 12, 3, 1, 4, 16, 25, 6, 34, 0, 32, 20, 22, 27, 11, 7, 0, 5, 37, 31, 28, 18, 19, 29, 10, 0] | D23: 3.7448993 | E23: A | F23: A_n37 | G23: A-n38-k5 | H23: vrp_100 | I23: 1 | J23: 730 | K23: 730 | L23: 0 | M23: 0 | N23: =IFERROR(B23/J23-1,"") -> 0.036940985 | P23: 1 | Q23: 0 | R23: 0 | T23: A-n38-k5
A24: 22 | B24: 739.6275 | C24: [0, 32, 20, 22, 27, 11, 7, 0, 5, 37, 31, 28, 6, 34, 29, 0, 18, 19, 25, 16, 4, 1, 3, 12, 26, 10, 0, 21, 30, 23, 35, 33, 8, 0, 24, 14, 2, 15, 13, 36, 17, 9, 0] | D24: 4.0925169 | E24: A | F24: A_n37 | G24: A-n38-k5 | H24: vrp_20 | I24: 1 | J24: 730 | K24: 0 | L24: 0 | M24: 730 | N24: =IFERROR(B24/J24-1,"") -> 0.01318836 | P24: 0 | Q24: 0 | R24: 1 | V24: A-n38-k5
A25: 23 | B25: 773.60059 | C25: [0, 8, 33, 35, 23, 26, 30, 0, 21, 10, 12, 3, 1, 4, 16, 25, 6, 19, 0, 24, 14, 2, 15, 13, 36, 17, 9, 0, 18, 29, 34, 37, 31, 28, 0, 7, 5, 11, 27, 22, 32, 0, 20, 0] | D25: 3.6349518 | E25: A | F25: A_n37 | G25: A-n38-k5 | H25: vrp_50 | I25: 1 | J25: 730 | K25: 0 | L25: 730 | M25: 0 | N25: =IFERROR(B25/J25-1,"") -> 0.05972683 | P25: 0 | Q25: 1 | R25: 0 | U25: A-n38-k5
A26: 24 | B26: 854.55505 | C26: [0, 36, 27, 34, 37, 35, 24, 0, 21, 30, 13, 28, 6, 26, 11, 8, 4, 0, 17, 2, 22, 3, 7, 16, 32, 38, 0, 31, 1, 15, 10, 5, 29, 20, 23, 33, 0, 14, 19, 25, 12, 9, 18, 0] | D26: 3.7533278 | E26: A | F26: A_n38 | G26: A-n39-k5 | H26: vrp_100 | I26: 2 | J26: 822 | K26: 822 | L26: 0 | M26: 0 | N26: =IFERROR(B26/J26-1,"") -> 0.039604688 | P26: 2 | Q26: 0 | R26: 0 | T26: A-n39-k5
A27: 25 | B27: 878.11194 | C27: [0, 20, 32, 27, 10, 16, 4, 7, 30, 0, 8, 19, 33, 2, 14, 25, 35, 31, 0, 18, 34, 22, 21, 23, 17, 36, 1, 0, 15, 13, 0, 3, 37, 38, 12, 9, 28, 29, 0, 24, 5, 26, 11, 6, 0] | D27: 3.7533278 | E27: A | F27: A_n38 | G27: A-n39-k6 | H27: vrp_100 | I27: 2 | J27: 831 | K27: 831 | L27: 0 | M27: 0 | N27: =IFERROR(B27/J27-1,"") -> 0.056693067 | P27: 2 | Q27: 0 | R27: 0 | T27: A-n39-k6
A28: 26 | B28: 839.70087 | C28: [0, 21, 30, 13, 28, 27, 36, 6, 8, 0, 11, 26, 34, 37, 35, 24, 17, 18, 0, 38, 15, 2, 22, 3, 7, 16, 29, 1, 0, 9, 10, 32, 5, 20, 23, 31, 0, 4, 12, 33, 25, 19, 14, 0] | D28: 3.0453658 | E28: A | F28: A_n38 | G28: A-n39-k5 | H28: vrp_20 | I28: 2 | J28: 822 | K28: 0 | L28: 0 | M28: 822 | N28: =IFERROR(B28/J28-1,"") -> 0.021533901 | P28: 0 | Q28: 0 | R28: 2 | V28: A-n39-k5
A29: 27 | B29: 836.5639 | C29: [0, 5, 29, 28, 9, 12, 38, 3, 24, 0, 37, 31, 14, 35, 25, 33, 19, 2, 0, 30, 7, 8, 4, 16, 10, 27, 32, 0, 20, 18, 34, 22, 21, 23, 17, 36, 1, 0, 6, 11, 26, 0, 13, 15, 0] | D29: 3.0453658 | E29: A | F29: A_n38 | G29: A-n39-k6 | H29: vrp_20 | I29: 2 | J29: 831 | K29: 0 | L29: 0 | M29: 831 | N29: =IFERROR(B29/J29-1,"") -> 0.0066954318 | P29: 0 | Q29: 0 | R29: 2 | V29: A-n39-k6
A30: 28 | B30: 833.41528 | C30: [0, 21, 30, 13, 28, 27, 36, 6, 0, 17, 24, 35, 37, 34, 26, 11, 8, 0, 2, 22, 3, 7, 16, 32, 10, 31, 0, 38, 15, 5, 29, 20, 23, 1, 12, 0, 4, 9, 18, 33, 25, 19, 14, 0] | D30: 0.19466853 | E30: A | F30: A_n38 | G30: A-n39-k5 | H30: vrp_50 | I30: 2 | J30: 822 | K30: 0 | L30: 822 | M30: 0 | N30: =IFERROR(B30/J30-1,"") -> 0.013887206 | P30: 0 | Q30: 2 | R30: 0 | U30: A-n39-k5
A31: 29 | B31: 835.28296 | C31: [0, 3, 12, 38, 37, 31, 35, 25, 14, 0, 30, 7, 8, 4, 19, 33, 2, 0, 20, 32, 10, 16, 27, 34, 22, 18, 0, 6, 1, 21, 23, 17, 36, 11, 0, 24, 29, 28, 9, 5, 26, 0, 15, 13, 0] | D31: 0.19466853 | E31: A | F31: A_n38 | G31: A-n39-k6 | H31: vrp_50 | I31: 2 | J31: 831 | K31: 0 | L31: 831 | M31: 0 | N31: =IFERROR(B31/J31-1,"") -> 0.0051539819 | P31: 0 | Q31: 2 | R31: 0 | U31: A-n39-k6
A32: 30 | B32: 966.24603 | C32: [0, 8, 7, 28, 27, 19, 4, 0, 15, 24, 5, 21, 32, 42, 37, 11, 10, 33, 0, 23, 30, 20, 16, 26, 39, 0, 22, 36, 9, 38, 13, 14, 41, 2, 0, 29, 43, 1, 35, 18, 40, 25, 0, 6, 3, 12, 17, 34, 31, 0] | D32: 3.646445 | E32: A | F32: A_n43 | G32: A-n44-k6 | H32: vrp_100 | I32: 1 | J32: 937 | K32: 937 | L32: 0 | M32: 0 | N32: =IFERROR(B32/J32-1,"") -> 0.031212415 | P32: 1 | Q32: 0 | R32: 0 | T32: A-n44-k6
A33: 31 | B33: 959.27039 | C33: [0, 8, 7, 28, 27, 19, 4, 0, 15, 5, 21, 32, 42, 37, 11, 10, 33, 24, 0, 26, 16, 20, 18, 35, 1, 30, 0, 34, 39, 23, 40, 29, 43, 13, 9, 0, 6, 25, 3, 12, 17, 31, 0, 22, 36, 38, 14, 41, 2, 0] | D33: 2.4535391 | E33: A | F33: A_n43 | G33: A-n44-k6 | H33: vrp_20 | I33: 1 | J33: 937 | K33: 0 | L33: 0 | M33: 937 | N33: =IFERROR(B33/J33-1,"") -> 0.023767754 | P33: 0 | Q33: 0 | R33: 1 | V33: A-n44-k6
A34: 32 | B34: 956.11902 | C34: [0, 7, 28, 27, 24, 33, 19, 8, 0, 15, 5, 21, 32, 42, 37, 11, 10, 26, 39, 0, 16, 20, 18, 35, 1, 30, 12, 0, 41, 14, 13, 38, 9, 36, 2, 0, 22, 43, 29, 40, 23, 25, 0, 6, 3, 17, 34, 4, 31, 0] | D34: 4.325841 | E34: A | F34: A_n43 | G34: A-n44-k6 | H34: vrp_50 | I34: 1 | J34: 937 | K34: 0 | L34: 937 | M34: 0 | N34: =IFERROR(B34/J34-1,"") -> 0.020404502 | P34: 0 | Q34: 1 | R34: 0 | U34: A-n44-k6
A35: 33 | B35: 994.26282 | C35: [0, 38, 31, 35, 14, 1, 0, 2, 25, 12, 39, 36, 15, 0, 44, 6, 24, 37, 34, 27, 0, 9, 22, 16, 4, 42, 23, 0, 3, 10, 8, 41, 33, 21, 5, 20, 32, 0, 11, 19, 30, 40, 17, 18, 43, 0, 26, 29, 13, 7, 28, 0] | D35: 3.7981927 | E35: A | F35: A_n44 | G35: A-n45-k6 | H35: vrp_100 | I35: 2 | J35: 944 | K35: 944 | L35: 0 | M35: 0 | N35: =IFERROR(B35/J35-1,"") -> 0.05324451 | P35: 2 | Q35: 0 | R35: 0 | T35: A-n45-k6
A36: 34 | B36: 1182.2603 | C36: [0, 12, 4, 26, 34, 35, 0, 2, 6, 28, 3, 11, 43, 41, 27, 21, 0, 40, 7, 16, 20, 38, 8, 32, 13, 18, 0, 17, 23, 25, 42, 15, 9, 0, 24, 44, 33, 39, 0, 5, 19, 36, 29, 31, 14, 0, 22, 30, 37, 1, 10, 0] | D36: 3.7981927 | E36: A | F36: A_n44 | G36: A-n45-k7 | H36: vrp_100 | I36: 2 | J36: 1146 | K36: 1146 | L36: 0 | M36: 0 | N36: =IFERROR(B36/J36-1,"") -> 0.03164071 | P36: 2 | Q36: 0 | R36: 0 | T36: A-n45-k7
A37: 35 | B37: 992.28864 | C37: [0, 2, 25, 12, 39, 36, 42, 4, 16, 9, 23, 0, 15, 22, 10, 8, 41, 33, 21, 5, 32, 0, 3, 20, 13, 7, 28, 0, 43, 18, 17, 40, 30, 19, 11, 0, 26, 29, 27, 34, 37, 24, 0, 6, 44, 1, 35, 31, 14, 0, 38, 0] | D37: 2.617625 | E37: A | F37: A_n44 | G37: A-n45-k6 | H37: vrp_20 | I37: 2 | J37: 944 | K37: 0 | L37: 0 | M37: 944 | N37: =IFERROR(B37/J37-1,"") -> 0.051153215 | P37: 0 | Q37: 0 | R37: 2 | V37: A-n45-k6
A38: 36 | B38: 1179.9366 | C38: [0, 18, 40, 7, 20, 16, 13, 32, 39, 0, 8, 10, 15, 25, 23, 17, 38, 0, 42, 1, 37, 30, 22, 9, 0, 5, 36, 19, 29, 31, 14, 21, 0, 24, 33, 27, 41, 43, 6, 0, 26, 44, 11, 3, 28, 12, 0, 35, 34, 4, 2, 0] | D38: 2.617625 | E38: A | F38: A_n44 | G38: A-n45-k7 | H38: vrp_20 | I38: 2 | J38: 1146 | K38: 0 | L38: 0 | M38: 1146 | N38: =IFERROR(B38/J38-1,"") -> 0.029613129 | P38: 0 | Q38: 0 | R38: 2 | V38: A-n45-k7
A39: 37 | B39: 991.6286 | C39: [0, 14, 31, 35, 1, 44, 6, 0, 38, 2, 25, 12, 39, 36, 15, 23, 0, 24, 37, 34, 19, 30, 40, 11, 0, 42, 4, 16, 22, 9, 0, 3, 10, 8, 41, 33, 21, 5, 20, 32, 0, 26, 29, 43, 17, 18, 27, 0, 28, 7, 13, 0] | D39: 4.8942862 | E39: A | F39: A_n44 | G39: A-n45-k6 | H39: vrp_50 | I39: 2 | J39: 944 | K39: 0 | L39: 944 | M39: 0 | N39: =IFERROR(B39/J39-1,"") -> 0.050454027 | P39: 0 | Q39: 2 | R39: 0 | U39: A-n45-k6
A40: 38 | B40: 1159.5055 | C40: [0, 12, 2, 4, 26, 34, 35, 0, 6, 28, 3, 11, 43, 41, 27, 21, 0, 24, 44, 33, 14, 9, 0, 39, 31, 29, 36, 19, 5, 0, 38, 25, 42, 1, 37, 30, 22, 0, 8, 17, 23, 15, 10, 32, 0, 40, 7, 20, 16, 18, 13, 0] | D40: 4.8942862 | E40: A | F40: A_n44 | G40: A-n45-k7 | H40: vrp_50 | I40: 2 | J40: 1146 | K40: 0 | L40: 1146 | M40: 0 | N40: =IFERROR(B40/J40-1,"") -> 0.011784898 | P40: 0 | Q40: 2 | R40: 0 | U40: A-n45-k7
...

Sheet Planilha2
A1: ID | B1: instance | E1: name | I1: ID | J1: instance | M1: ID | N1: instance
A2: 0 | B2: A_n31 | C2: 1 | D2: A_n31 | E2: A-n32-k5 | F2: 1 | G2: 784 | I2: 2 | J2: A_n31 | K2: TRUE | M2: 1 | N2: A_n31 | O2: TRUE
A3: 3 | B3: A_n32 | C3: 2 | D3: A_n32 | E3: A-n33-k5 | F3: 1 | G3: 661 | I3: 7 | J3: A_n32 | K3: TRUE | M3: 5 | N3: A_n32 | O3: TRUE
A4: 4 | B4: A_n32 | C4: 2 | D4: A_n32_1 | E4: A-n33-k6 | F4: 1 | G4: 742 | I4: 8 | J4: A_n32 | K4: TRUE | M4: 6 | N4: A_n32 | O4: TRUE
A5: 9 | B5: A_n33 | C5: 1 | D5: A_n33 | E5: A-n34-k5 | F5: 1 | G5: 778 | I5: 11 | J5: A_n33 | K5: TRUE | M5: 10 | N5: A_n33 | O5: TRUE
A6: 12 | B6: A_n35 | C6: 1 | D6: A_n35 | E6: A-n36-k5 | F6: 1 | G6: 799 | I6: 14 | J6: A_n35 | K6: TRUE | M6: 13 | N6: A_n35 | O6: TRUE
A7: 15 | B7: A_n36 | C7: 2 | D7: A_n36 | E7: A-n37-k5 | F7: 1 | G7: 669 | I7: 19 | J7: A_n36 | K7: TRUE | M7: 17 | N7: A_n36 | O7: TRUE
A8: 16 | B8: A_n36 | C8: 2 | D8: A_n36_1 | E8: A-n37-k6 | F8: 1 | G8: 949 | I8: 20 | J8: A_n36 | K8: TRUE | M8: 18 | N8: A_n36 | O8: TRUE
A9: 21 | B9: A_n37 | C9: 1 | D9: A_n37 | E9: A-n38-k5 | F9: 1 | G9: 730 | I9: 23 | J9: A_n37 | K9: TRUE | M9: 22 | N9: A_n37 | O9: TRUE
A10: 24 | B10: A_n38 | C10: 2 | D10: A_n38 | E10: A-n39-k5 | F10: 1 | G10: 822 | I10: 28 | J10: A_n38 | K10: TRUE | M10: 26 | N10: A_n38 | O10: TRUE
A11: 25 | B11: A_n38 | C11: 2 | D11: A_n38_1 | E11: A-n39-k6 | F11: 1 | G11: 831 | I11: 29 | J11: A_n38 | K11: TRUE | M11: 27 | N11: A_n38 | O11: TRUE
A12: 30 | B12: A_n43 | C12: 1 | D12: A_n43 | E12: A-n44-k6 | F12: 1 | G12: 937 | I12: 32 | J12: A_n43 | K12: TRUE | M12: 31 | N12: A_n43 | O12: TRUE
A13: 33 | B13: A_n44 | C13: 2 | D13: A_n44 | E13: A-n45-k6 | F13: 1 | G13: 944 | I13: 37 | J13: A_n44 | K13: TRUE | M13: 35 | N13: A_n44 | O13: TRUE
... A86: 252 | B86: Li_n1040 | C86: 1 | D86: Li_n1040 | E86: Li_30 | F86: 1 | G86: 31742.639 | I86: 255 | J86: Li_n1040 | K86: TRUE | M86: 253 | N86: Li_n1040 | O86: TRUE
A87: 256 | B87: Li_n1120 | C87: 1 | D87: Li_n1120 | E87: Li_31 | F87: 1 | G87: 34330.94 | I87: 258 | J87: Li_n1120 | K87: TRUE | M87: 257 | N87: Li_n1120 | O87: TRUE | R87: 254 | S87: Li_n1040 | T87: FALSE
A88: 259 | B88: Li_n1200 | C88: 1 | D88: Li_n1200 | E88: Li_32 | F88: 1 | G88: 37159.413 | I88: 261 | J88: Li_n1200 | K88: TRUE | M88: 260 | N88: Li_n1200 | O88: TRUE
A89: 262 | B89: Li_n560 | C89: 1 | D89: Li_n560 | E89: Li_21 | F89: 1 | G89: 16212.825 | I89: 264 | J89: Li_n560 | K89: TRUE | M89: 263 | N89: Li_n560 | O89: TRUE
A90: 265 | B90: Li_n600 | C90: 1 | D90: Li_n600 | E90: Li_22 | F90: 1 | G90: 14499.045 | I90: 267 | J90: Li_n600 | K90: TRUE | M90: 266 | N90: Li_n600 | O90: TRUE
A91: 268 | B91: Li_n640 | C91: 1 | D91: Li_n640 | E91: Li_23 | F91: 1 | G91: 18801.128 | I91: 270 | J91: Li_n640 | K91: TRUE | M91: 269 | N91: Li_n640 | O91: TRUE
A92: 271 | B92: Li_n720 | C92: 1 | D92: Li_n720 | E92: Li_24 | F92: 1 | G92: 21389.43 | I92: 273 | J92: Li_n720 | K92: TRUE | M92: 272 | N92: Li_n720 | O92: TRUE
A93: 274 | B93: Li_n760 | C93: 1 | D93: Li_n760 | E93: Li_25 | F93: 1 | G93: 16665.7 | I93: 276 | J93: Li_n760 | K93: TRUE | M93: 275 | N93: Li_n760 | O93: TRUE
A94: 277 | B94: Li_n800 | C94: 1 | D94: Li_n800 | E94: Li_26 | F94: 1 | G94: 23977.733 | I94: 279 | J94: Li_n800 | K94: TRUE | M94: 278 | N94: Li_n800 | O94: TRUE
A95: 280 | B95: Li_n840 | C95: 1 | D95: Li_n840 | E95: Li_27 | F95: 1 | G95: 17320 | I95: 282 | J95: Li_n840 | K95: TRUE | M95: 281 | N95: Li_n840 | O95: TRUE
A96: 283 | B96: Li_n880 | C96: 1 | D96: Li_n880 | E96: Li_28 | F96: 1 | G96: 26566.034 | I96: 285 | J96: Li_n880 | K96: TRUE | M96: 284 | N96: Li_n880 | O96: TRUE
A97: 286 | B97: Li_n960 | C97: 1 | D97: Li_n960 | E97: Li_29 | F97: 1 | G97: 29154.336 | I97: 288 | J97: Li_n960 | K97: TRUE | M97: 287 | N97: Li_n960 | O97: TRUE
A98: 289 | B98: M_n100 | C98: 1 | D98: M_n100 | E98: M-n101-k10 | F98: 1 | G98: 820 | I98: 291 | J98: M_n100 | K98: TRUE | M98: 290 | N98: M_n100 | O98: TRUE
A99: 292 | B99: M_n120 | C99: 1 | D99: M_n120 | E99: M-n121-k7 | F99: 1 | G99: 1034 | I99: 294 | J99: M_n120 | K99: TRUE | M99: 293 | N99: M_n120 | O99: TRUE
... A139: 406 | B139: Taillard_n75 | C139: 4 | D139: Taillard_n75_3 | E139: Tai75d | F139: 1 | G139: 1365.42 | I139: 414 | J139: Taillard_n75 | K139: TRUE | M139: 410 | N139: Taillard_n75 | O139: TRUE
A140: 415 | B140: X_n100 | C140: 2 | D140: X_n100 | E140: X-n101-k25 | F140: 1 | G140: 27591 | I140: 418 | J140: X_n100 | K140: TRUE
A141: 416 | B141: X_n100 | C141: 2 | D141: X_n100_1 | F141: 0 | M141: 417 | N141: X_n100 | O141: TRUE
A142: 419 | B142: X_n1000 | C142: 1 | D142: X_n1000 | E142: X-n1001-k43 | F142: 1 | G142: 72355 | I142: 421 | J142: X_n1000 | K142: TRUE | M142: 420 | N142: X_n1000 | O142: TRUE
A143: 422 | B143: X_n105 | C143: 1 | D143: X_n105 | E143: X-n106-k14 | F143: 1 | G143: 26362 | I143: 424 | J143: X_n105 | K143: TRUE | M143: 423 | N143: X_n105 | O143: TRUE
A144: 425 | B144: X_n109 | C144: 1 | D144: X_n109 | E144: X-n110-k13 | F144: 1 | G144: 14971 | I144: 427 | J144: X_n109 | K144: TRUE | M144: 426 | N144: X_n109 | O144: TRUE
A145: 428 | B145: X_n114 | C145: 1 | D145: X_n114 | E145: X-n115-k10 | F145: 1 | G145: 12747 | I145: 430 | J145: X_n114 | K145: TRUE | M145: 429 | N145: X_n114 | O145: TRUE
A146: 431 | B146: X_n119 | C146: 1 | D146: X_n119 | E146: X-n120-k6 | F146: 1 | G146: 13332 | I146: 433 | J146: X_n119 | K146: TRUE | M146: 432 | N146: X_n119 | O146: TRUE
A147: 434 | B147: X_n124 | C147: 1 | D147: X_n124 | E147: X-n125-k30 | F147: 1 | G147: 55539 | I147: 436 | J147: X_n124 | K147: TRUE | M147: 435 | N147: X_n124 | O147: TRUE
A148: 437 | B148: X_n128 | C148: 1 | D148: X_n128 | E148: X-n129-k18 | F148: 1 | G148: 28940 | I148: 439 | J148: X_n128 | K148: TRUE | M148: 438 | N148: X_n128 | O148: TRUE
A149: 440 | B149: X_n133 | C149: 1 | D149: X_n133 | E149: X-n134-k13 | F149: 1 | G149: 10916 | I149: 442 | J149: X_n133 | K149: TRUE | M149: 441 | N149: X_n133 | O149: TRUE
A150: 443 | B150: X_n138 | C150: 1 | D150: X_n138 | E150: X-n139-k10 | F150: 1 | G150: 13590 | I150: 445 | J150: X_n138 | K150: TRUE | M150: 444 | N150: X_n138 | O150: TRUE
A151: 446 | B151: X_n142 | C151: 1 | D151: X_n142 | E151: X-n143-k7 | F151: 1 | G151: 15700 | I151: 448 | J151: X_n142 | K151: TRUE | M151: 447 | N151: X_n142 | O151: TRUE
...

Sheet Analise_Instancias
A1: Set | B1: Instância | C1: n clientes | D1: BKS | E1: Custo vrp_20 | F1: Gap vrp_20 | G1: Tempo vrp_20 | H1: Custo vrp_50 | I1: Gap vrp_50 | J1: Tempo vrp_50 | K1: Custo vrp_100 | L1: Gap vrp_100 | M1: Tempo vrp_100 | N1: Melhor custo | O1: Melhor gap | P1: Melhor modelo | Q1: Tempo portfólio | R1: Faixa tamanho | S1: Classe gap | T1: Flag auditoria | U1: Tempo modelo escolhido | V1: Ganho portfólio vs vrp_100
A2: A | B2: A-n32-k5 | C2: 31 | D2: =Data!J2 -> 784 | E2: =Data!B3 -> 792.38147 | F2: =IF(E2="","",IFERROR(E2/D2-1,"")) -> 0.01069065 | G2: =Data!D3 -> 2.458679 | H2: =Data!B4 -> 832.48456 | I2: =IF(H2="","",IFERROR(H2/D2-1,"")) -> 0.061842549 | J2: =Data!D4 -> 3.4842 | K2: =Data!B2 -> 833.01886 | L2: =IF(K2="","",IFERROR(K2/D2-1,"")) -> 0.062524056 | M2: =Data!D2 -> 3.2406287 | N2: =MIN(E2,H2,K2) -> 792.38147 | O2: =MIN(F2,I2,L2) -> 0.01069065 | P2: =IF(N2=E2,"vrp_20",IF(N2=H2,"vrp_50","vrp_100")) -> vrp_20 | Q2: =SUM(G2,J2,M2) -> 9.1835077 | R2: =IF(C2<=50,"≤50",IF(C2<=100,"51-100",IF(C2<=200,"101-200",IF(C2<=500,"201-500",">500")))) -> ≤50 | S2: =IF(O2<=0,"≤0%",IF(O2<=0.01,"0-1%",IF(O2<=0.02,"1-2%",IF(O2<=0.05,"2-5%",IF(O2<=0.1,"5-10%",">10%"))))) -> 1-2% | T2: =IF(O2<0,"VERIFICAR: gap < 0",IF(O2>0.2,"ATENÇÃO: gap > 20%","")) | U2: =IF(P2="vrp_20",G2,IF(P2="vrp_50",J2,M2)) -> 2.458679 | V2: =L2-O2 -> 0.051833406
A3: A | B3: A-n33-k5 | C3: 32 | D3: =Data!J5 -> 661 | E3: =Data!B7 -> 674.85706 | F3: =IF(E3="","",IFERROR(E3/D3-1,"")) -> 0.020963776 | G3: =Data!D7 -> 1.9951878 | H3: =Data!B9 -> 674.11652 | I3: =IF(H3="","",IFERROR(H3/D3-1,"")) -> 0.019843443 | J3: =Data!D9 -> 3.653559 | K3: =Data!B5 -> 730.66632 | L3: =IF(K3="","",IFERROR(K3/D3-1,"")) -> 0.10539534 | M3: =Data!D5 -> 3.5166168 | N3: =MIN(E3,H3,K3) -> 674.11652 | O3: =MIN(F3,I3,L3) -> 0.019843443 | P3: =IF(N3=E3,"vrp_20",IF(N3=H3,"vrp_50","vrp_100")) -> vrp_50 | Q3: =SUM(G3,J3,M3) -> 9.1653636 | R3: =IF(C3<=50,"≤50",IF(C3<=100,"51-100",IF(C3<=200,"101-200",IF(C3<=500,"201-500",">500")))) -> ≤50 | S3: =IF(O3<=0,"≤0%",IF(O3<=0.01,"0-1%",IF(O3<=0.02,"1-2%",IF(O3<=0.05,"2-5%",IF(O3<=0.1,"5-10%",">10%"))))) -> 1-2% | T3: =IF(O3<0,"VERIFICAR: gap < 0",IF(O3>0.2,"ATENÇÃO: gap > 20%","")) | U3: =IF(P3="vrp_20",G3,IF(P3="vrp_50",J3,M3)) -> 3.653559 | V3: =L3-O3 -> 0.085551898
A4: A | B4: A-n33-k6 | C4: 32 | D4: =Data!J6 -> 742 | E4: =Data!B8 -> 762.57526 | F4: =IF(E4="","",IFERROR(E4/D4-1,"")) -> 0.027729456 | G4: =Data!D8 -> 1.9951878 | H4: =Data!B10 -> 744.56445 | I4: =IF(H4="","",IFERROR(H4/D4-1,"")) -> 0.0034561363 | J4: =Data!D10 -> 3.653559 | K4: =Data!B6 -> 777.43854 | L4: =IF(K4="","",IFERROR(K4/D4-1,"")) -> 0.047760832 | M4: =Data!D6 -> 3.5166168 | N4: =MIN(E4,H4,K4) -> 744.56445 | O4: =MIN(F4,I4,L4) -> 0.0034561363 | P4: =IF(N4=E4,"vrp_20",IF(N4=H4,"vrp_50","vrp_100")) -> vrp_50 | Q4: =SUM(G4,J4,M4) -> 9.1653636 | R4: =IF(C4<=50,"≤50",IF(C4<=100,"51-100",IF(C4<=200,"101-200",IF(C4<=500,"201-500",">500")))) -> ≤50 | S4: =IF(O4<=0,"≤0%",IF(O4<=0.01,"0-1%",IF(O4<=0.02,"1-2%",IF(O4<=0.05,"2-5%",IF(O4<=0.1,"5-10%",">10%"))))) -> 0-1% | T4: =IF(O4<0,"VERIFICAR: gap < 0",IF(O4>0.2,"ATENÇÃO: gap > 20%","")) | U4: =IF(P4="vrp_20",G4,IF(P4="vrp_50",J4,M4)) -> 3.653559 | V4: =L4-O4 -> 0.044304696
A5: A | B5: A-n34-k5 | C5: 33 | D5: =Data!J11 -> 778 | E5: =Data!B12 -> 802.79089 | F5: =IF(E5="","",IFERROR(E5/D5-1,"")) -> 0.031864902 | G5: =Data!D12 -> 1.9882326 | H5: =Data!B13 -> 790.22095 | I5: =IF(H5="","",IFERROR(H5/D5-1,"")) -> 0.015708158 | J5: =Data!D13 -> 3.712981 | K5: =Data!B11 -> 787.43042 | L5: =IF(K5="","",IFERROR(K5/D5-1,"")) -> 0.012121362 | M5: =Data!D11 -> 3.6198652 | N5: =MIN(E5,H5,K5) -> 787.43042 | O5: =MIN(F5,I5,L5) -> 0.012121362 | P5: =IF(N5=E5,"vrp_20",IF(N5=H5,"vrp_50","vrp_100")) -> vrp_100 | Q5: =SUM(G5,J5,M5) -> 9.3210788 | R5: =IF(C5<=50,"≤50",IF(C5<=100,"51-100",IF(C5<=200,"101-200",IF(C5<=500,"201-500",">500")))) -> ≤50 | S5: =IF(O5<=0,"≤0%",IF(O5<=0.01,"0-1%",IF(O5<=0.02,"1-2%",IF(O5<=0.05,"2-5%",IF(O5<=0.1,"5-10%",">10%"))))) -> 1-2% | T5: =IF(O5<0,"VERIFICAR: gap < 0",IF(O5>0.2,"ATENÇÃO: gap > 20%","")) | U5: =IF(P5="vrp_20",G5,IF(P5="vrp_50",J5,M5)) -> 3.6198652 | V5: =L5-O5 -> 0
A6: A | B6: A-n36-k5 | C6: 35 | D6: =Data!J14 -> 799 | E6: =Data!B15 -> 821.14111 | F6: =IF(E6="","",IFERROR(E6/D6-1,"")) -> 0.02771103 | G6: =Data!D15 -> 2.277431 | H6: =Data!B16 -> 868.58826 | I6: =IF(H6="","",IFERROR(H6/D6-1,"")) -> 0.087094189 | J6: =Data!D16 -> 3.8794634 | K6: =Data!B14 -> 810.0708 | L6: =IF(K6="","",IFERROR(K6/D6-1,"")) -> 0.013855821 | M6: =Data!D14 -> 3.7884512 | N6: =MIN(E6,H6,K6) -> 810.0708 | O6: =MIN(F6,I6,L6) -> 0.013855821 | P6: =IF(N6=E6,"vrp_20",IF(N6=H6,"vrp_50","vrp_100")) -> vrp_100 | Q6: =SUM(G6,J6,M6) -> 9.9453456 | R6: =IF(C6<=50,"≤50",IF(C6<=100,"51-100",IF(C6<=200,"101-200",IF(C6<=500,"201-500",">500")))) -> ≤50 | S6: =IF(O6<=0,"≤0%",IF(O6<=0.01,"0-1%",IF(O6<=0.02,"1-2%",IF(O6<=0.05,"2-5%",IF(O6<=0.1,"5-10%",">10%"))))) -> 1-2% | T6: =IF(O6<0,"VERIFICAR: gap < 0",IF(O6>0.2,"ATENÇÃO: gap > 20%","")) | U6: =IF(P6="vrp_20",G6,IF(P6="vrp_50",J6,M6)) -> 3.7884512 | V6: =L6-O6 -> 0
A7: A | B7: A-n37-k5 | C7: 36 | D7: =Data!J17 -> 669 | E7: =Data!B19 -> 697.43799 | F7: =IF(E7="","",IFERROR(E7/D7-1,"")) -> 0.042508204 | G7: =Data!D19 -> 4.4269788 | H7: =Data!B21 -> 698.95752 | I7: =IF(H7="","",IFERROR(H7/D7-1,"")) -> 0.044779551 | J7: =Data!D21 -> 3.9273241 | K7: =Data!B17 -> 740.34631 | L7: =IF(K7="","",IFERROR(K7/D7-1,"")) -> 0.10664621 | M7: =Data!D17 -> 3.6620553 | N7: =MIN(E7,H7,K7) -> 697.43799 | O7: =MIN(F7,I7,L7) -> 0.042508204 | P7: =IF(N7=E7,"vrp_20",IF(N7=H7,"vrp_50","vrp_100")) -> vrp_20 | Q7: =SUM(G7,J7,M7) -> 12.016358 | R7: =IF(C7<=50,"≤50",IF(C7<=100,"51-100",IF(C7<=200,"101-200",IF(C7<=500,"201-500",">500")))) -> ≤50 | S7: =IF(O7<=0,"≤0%",IF(O7<=0.01,"0-1%",IF(O7<=0.02,"1-2%",IF(O7<=0.05,"2-5%",IF(O7<=0.1,"5-10%",">10%"))))) -> 2-5% | T7: =IF(O7<0,"VERIFICAR: gap < 0",IF(O7>0.2,"ATENÇÃO: gap > 20%","")) | U7: =IF(P7="vrp_20",G7,IF(P7="vrp_50",J7,M7)) -> 4.4269788 | V7: =L7-O7 -> 0.064138005
A8: A | B8: A-n37-k6 | C8: 36 | D8: =Data!J18 -> 949 | E8: =Data!B20 -> 981.73938 | F8: =IF(E8="","",IFERROR(E8/D8-1,"")) -> 0.03449882 | G8: =Data!D20 -> 4.4269788 | H8: =Data!B22 -> 957.02979 | I8: =IF(H8="","",IFERROR(H8/D8-1,"")) -> 0.0084613121 | J8: =Data!D22 -> 3.9273241 | K8: =Data!B18 -> 956.7439 | L8: =IF(K8="","",IFERROR(K8/D8-1,"")) -> 0.0081600595 | M8: =Data!D18 -> 3.6620553 | N8: =MIN(E8,H8,K8) -> 956.7439 | O8: =MIN(F8,I8,L8) -> 0.0081600595 | P8: =IF(N8=E8,"vrp_20",IF(N8=H8,"vrp_50","vrp_100")) -> vrp_100 | Q8: =SUM(G8,J8,M8) -> 12.016358 | R8: =IF(C8<=50,"≤50",IF(C8<=100,"51-100",IF(C8<=200,"101-200",IF(C8<=500,"201-500",">500")))) -> ≤50 | S8: =IF(O8<=0,"≤0%",IF(O8<=0.01,"0-1%",IF(O8<=0.02,"1-2%",IF(O8<=0.05,"2-5%",IF(O8<=0.1,"5-10%",">10%"))))) -> 0-1% | T8: =IF(O8<0,"VERIFICAR: gap < 0",IF(O8>0.2,"ATENÇÃO: gap > 20%","")) | U8: =IF(P8="vrp_20",G8,IF(P8="vrp_50",J8,M8)) -> 3.6620553 | V8: =L8-O8 -> 0
A9: A | B9: A-n38-k5 | C9: 37 | D9: =Data!J23 -> 730 | E9: =Data!B24 -> 739.6275 | F9: =IF(E9="","",IFERROR(E9/D9-1,"")) -> 0.01318836 | G9: =Data!D24 -> 4.0925169 | H9: =Data!B25 -> 773.60059 | I9: =IF(H9="","",IFERROR(H9/D9-1,"")) -> 0.05972683 | J9: =Data!D25 -> 3.6349518 | K9: =Data!B23 -> 756.96692 | L9: =IF(K9="","",IFERROR(K9/D9-1,"")) -> 0.036940985 | M9: =Data!D23 -> 3.7448993 | N9: =MIN(E9,H9,K9) -> 739.6275 | O9: =MIN(F9,I9,L9) -> 0.01318836 | P9: =IF(N9=E9,"vrp_20",IF(N9=H9,"vrp_50","vrp_100")) -> vrp_20 | Q9: =SUM(G9,J9,M9) -> 11.472368 | R9: =IF(C9<=50,"≤50",IF(C9<=100,"51-100",IF(C9<=200,"101-200",IF(C9<=500,"201-500",">500")))) -> ≤50 | S9: =IF(O9<=0,"≤0%",IF(O9<=0.01,"0-1%",IF(O9<=0.02,"1-2%",IF(O9<=0.05,"2-5%",IF(O9<=0.1,"5-10%",">10%"))))) -> 1-2% | T9: =IF(O9<0,"VERIFICAR: gap < 0",IF(O9>0.2,"ATENÇÃO: gap > 20%","")) | U9: =IF(P9="vrp_20",G9,IF(P9="vrp_50",J9,M9)) -> 4.0925169 | V9: =L9-O9 -> 0.023752625
A10: A | B10: A-n39-k5 | C10: 38 | D10: =Data!J26 -> 822 | E10: =Data!B28 -> 839.70087 | F10: =IF(E10="","",IFERROR(E10/D10-1,"")) -> 0.021533901 | G10: =Data!D28 -> 3.0453658 | H10: =Data!B30 -> 833.41528 | I10: =IF(H10="","",IFERROR(H10/D10-1,"")) -> 0.013887206 | J10: =Data!D30 -> 0.19466853 | K10: =Data!B26 -> 854.55505 | L10: =IF(K10="","",IFERROR(K10/D10-1,"")) -> 0.039604688 | M10: =Data!D26 -> 3.7533278 | N10: =MIN(E10,H10,K10) -> 833.41528 | O10: =MIN(F10,I10,L10) -> 0.013887206 | P10: =IF(N10=E10,"vrp_20",IF(N10=H10,"vrp_50","vrp_100")) -> vrp_50 | Q10: =SUM(G10,J10,M10) -> 6.9933622 | R10: =IF(C10<=50,"≤50",IF(C10<=100,"51-100",IF(C10<=200,"101-200",IF(C10<=500,"201-500",">500")))) -> ≤50 | S10: =IF(O10<=0,"≤0%",IF(O10<=0.01,"0-1%",IF(O10<=0.02,"1-2%",IF(O10<=0.05,"2-5%",IF(O10<=0.1,"5-10%",">10%"))))) -> 1-2% | T10: =IF(O10<0,"VERIFICAR: gap < 0",IF(O10>0.2,"ATENÇÃO: gap > 20%","")) | U10: =IF(P10="vrp_20",G10,IF(P10="vrp_50",J10,M10)) -> 0.19466853 | V10: =L10-O10 -> 0.025717482
A11: A | B11: A-n39-k6 | C11: 38 | D11: =Data!J27 -> 831 | E11: =Data!B29 -> 836.5639 | F11: =IF(E11="","",IFERROR(E11/D11-1,"")) -> 0.0066954318 | G11: =Data!D29 -> 3.0453658 | H11: =Data!B31 -> 835.28296 | I11: =IF(H11="","",IFERROR(H11/D11-1,"")) -> 0.0051539819 | J11: =Data!D31 -> 0.19466853 | K11: =Data!B27 -> 878.11194 | L11: =IF(K11="","",IFERROR(K11/D11-1,"")) -> 0.056693067 | M11: =Data!D27 -> 3.7533278 | N11: =MIN(E11,H11,K11) -> 835.28296 | O11: =MIN(F11,I11,L11) -> 0.0051539819 | P11: =IF(N11=E11,"vrp_20",IF(N11=H11,"vrp_50","vrp_100")) -> vrp_50 | Q11: =SUM(G11,J11,M11) -> 6.9933622 | R11: =IF(C11<=50,"≤50",IF(C11<=100,"51-100",IF(C11<=200,"101-200",IF(C11<=500,"201-500",">500")))) -> ≤50 | S11: =IF(O11<=0,"≤0%",IF(O11<=0.01,"0-1%",IF(O11<=0.02,"1-2%",IF(O11<=0.05,"2-5%",IF(O11<=0.1,"5-10%",">10%"))))) -> 0-1% | T11: =IF(O11<0,"VERIFICAR: gap < 0",IF(O11>0.2,"ATENÇÃO: gap > 20%","")) | U11: =IF(P11="vrp_20",G11,IF(P11="vrp_50",J11,M11)) -> 0.19466853 | V11: =L11-O11 -> 0.051539085
A12: A | B12: A-n44-k6 | C12: 43 | D12: =Data!J32 -> 937 | E12: =Data!B33 -> 959.27039 | F12: =IF(E12="","",IFERROR(E12/D12-1,"")) -> 0.023767754 | G12: =Data!D33 -> 2.4535391 | H12: =Data!B34 -> 956.11902 | I12: =IF(H12="","",IFERROR(H12/D12-1,"")) -> 0.020404502 | J12: =Data!D34 -> 4.325841 | K12: =Data!B32 -> 966.24603 | L12: =IF(K12="","",IFERROR(K12/D12-1,"")) -> 0.031212415 | M12: =Data!D32 -> 3.646445 | N12: =MIN(E12,H12,K12) -> 956.11902 | O12: =MIN(F12,I12,L12) -> 0.020404502 | P12: =IF(N12=E12,"vrp_20",IF(N12=H12,"vrp_50","vrp_100")) -> vrp_50 | Q12: =SUM(G12,J12,M12) -> 10.425825 | R12: =IF(C12<=50,"≤50",IF(C12<=100,"51-100",IF(C12<=200,"101-200",IF(C12<=500,"201-500",">500")))) -> ≤50 | S12: =IF(O12<=0,"≤0%",IF(O12<=0.01,"0-1%",IF(O12<=0.02,"1-2%",IF(O12<=0.05,"2-5%",IF(O12<=0.1,"5-10%",">10%"))))) -> 2-5% | T12: =IF(O12<0,"VERIFICAR: gap < 0",IF(O12>0.2,"ATENÇÃO: gap > 20%","")) | U12: =IF(P12="vrp_20",G12,IF(P12="vrp_50",J12,M12)) -> 4.325841 | V12: =L12-O12 -> 0.010807913
A13: A | B13: A-n45-k6 | C13: 44 | D13: =Data!J35 -> 944 | E13: =Data!B37 -> 992.28864 | F13: =IF(E13="","",IFERROR(E13/D13-1,"")) -> 0.051153215 | G13: =Data!D37 -> 2.617625 | H13: =Data!B39 -> 991.6286 | I13: =IF(H13="","",IFERROR(H13/D13-1,"")) -> 0.050454027 | J13: =Data!D39 -> 4.8942862 | K13: =Data!B35 -> 994.26282 | L13: =IF(K13="","",IFERROR(K13/D13-1,"")) -> 0.05324451 | M13: =Data!D35 -> 3.7981927 | N13: =MIN(E13,H13,K13) -> 991.6286 | O13: =MIN(F13,I13,L13) -> 0.050454027 | P13: =IF(N13=E13,"vrp_20",IF(N13=H13,"vrp_50","vrp_100")) -> vrp_50 | Q13: =SUM(G13,J13,M13) -> 11.310104 | R13: =IF(C13<=50,"≤50",IF(C13<=100,"51-100",IF(C13<=200,"101-200",IF(C13<=500,"201-500",">500")))) -> ≤50 | S13: =IF(O13<=0,"≤0%",IF(O13<=0.01,"0-1%",IF(O13<=0.02,"1-2%",IF(O13<=0.05,"2-5%",IF(O13<=0.1,"5-10%",">10%"))))) -> 5-10% | T13: =IF(O13<0,"VERIFICAR: gap < 0",IF(O13>0.2,"ATENÇÃO: gap > 20%","")) | U13: =IF(P13="vrp_20",G13,IF(P13="vrp_50",J13,M13)) -> 4.8942862 | V13: =L13-O13 -> 0.0027904834
A14: A | B14: A-n45-k7 | C14: 44 | D14: =Data!J36 -> 1146 | E14: =Data!B38 -> 1179.9366 | F14: =IF(E14="","",IFERROR(E14/D14-1,"")) -> 0.029613129 | G14: =Data!D38 -> 2.617625 | H14: =Data!B40 -> 1159.5055 | I14: =IF(H14="","",IFERROR(H14/D14-1,"")) -> 0.011784898 | J14: =Data!D40 -> 4.8942862 | K14: =Data!B36 -> 1182.2603 | L14: =IF(K14="","",IFERROR(K14/D14-1,"")) -> 0.03164071 | M14: =Data!D36 -> 3.7981927 | N14: =MIN(E14,H14,K14) -> 1159.5055 | O14: =MIN(F14,I14,L14) -> 0.011784898 | P14: =IF(N14=E14,"vrp_20",IF(N14=H14,"vrp_50","vrp_100")) -> vrp_50 | Q14: =SUM(G14,J14,M14) -> 11.310104 | R14: =IF(C14<=50,"≤50",IF(C14<=100,"51-100",IF(C14<=200,"101-200",IF(C14<=500,"201-500",">500")))) -> ≤50 | S14: =IF(O14<=0,"≤0%",IF(O14<=0.01,"0-1%",IF(O14<=0.02,"1-2%",IF(O14<=0.05,"2-5%",IF(O14<=0.1,"5-10%",">10%"))))) -> 1-2% | T14: =IF(O14<0,"VERIFICAR: gap < 0",IF(O14>0.2,"ATENÇÃO: gap > 20%","")) | U14: =IF(P14="vrp_20",G14,IF(P14="vrp_50",J14,M14)) -> 4.8942862 | V14: =L14-O14 -> 0.019855812
A15: A | B15: A-n46-k7 | C15: 45 | D15: =Data!J41 -> 914 | E15: =Data!B42 -> 927.62164 | F15: =IF(E15="","",IFERROR(E15/D15-1,"")) -> 0.014903329 | G15: =Data!D42 -> 3.990844 | H15: =Data!B43 -> 924.70831 | I15: =IF(H15="","",IFERROR(H15/D15-1,"")) -> 0.011715879 | J15: =Data!D43 -> 5.347734 | K15: =Data!B41 -> 988.17242 | L15: =IF(K15="","",IFERROR(K15/D15-1,"")) -> 0.081151449 | M15: =Data!D41 -> 3.7958472 | N15: =MIN(E15,H15,K15) -> 924.70831 | O15: =MIN(F15,I15,L15) -> 0.011715879 | P15: =IF(N15=E15,"vrp_20",IF(N15=H15,"vrp_50","vrp_100")) -> vrp_50 | Q15: =SUM(G15,J15,M15) -> 13.134425 | R15: =IF(C15<=50,"≤50",IF(C15<=100,"51-100",IF(C15<=200,"101-200",IF(C15<=500,"201-500",">500")))) -> ≤50 | S15: =IF(O15<=0,"≤0%",IF(O15<=0.01,"0-1%",IF(O15<=0.02,"1-2%",IF(O15<=0.05,"2-5%",IF(O15<=0.1,"5-10%",">10%"))))) -> 1-2% | T15: =IF(O15<0,"VERIFICAR: gap < 0",IF(O15>0.2,"ATENÇÃO: gap > 20%","")) | U15: =IF(P15="vrp_20",G15,IF(P15="vrp_50",J15,M15)) -> 5.347734 | V15: =L15-O15 -> 0.06943557
A16: A | B16: A-n48-k7 | C16: 47 | D16: =Data!J44 -> 1073 | E16: =Data!B45 -> 1109.6693 | F16: =IF(E16="","",IFERROR(E16/D16-1,"")) -> 0.034174568 | G16: =Data!D45 -> 3.5602279 | H16: =Data!B46 -> 1103.5421 | I16: =IF(H16="","",IFERROR(H16/D16-1,"")) -> 0.028464226 | J16: =Data!D46 -> 3.5708776 | K16: =Data!B44 -> 1082.0381 | L16: =IF(K16="","",IFERROR(K16/D16-1,"")) -> 0.0084231929 | M16: =Data!D44 -> 3.7709935 | N16: =MIN(E16,H16,K16) -> 1082.0381 | O16: =MIN(F16,I16,L16) -> 0.0084231929 | P16: =IF(N16=E16,"vrp_20",IF(N16=H16,"vrp_50","vrp_100")) -> vrp_100 | Q16: =SUM(G16,J16,M16) -> 10.902099 | R16: =IF(C16<=50,"≤50",IF(C16<=100,"51-100",IF(C16<=200,"101-200",IF(C16<=500,"201-500",">500")))) -> ≤50 | S16: =IF(O16<=0,"≤0%",IF(O16<=0.01,"0-1%",IF(O16<=0.02,"1-2%",IF(O16<=0.05,"2-5%",IF(O16<=0.1,"5-10%",">10%"))))) -> 0-1% | T16: =IF(O16<0,"VERIFICAR: gap < 0",IF(O16>0.2,"ATENÇÃO: gap > 20%","")) | U16: =IF(P16="vrp_20",G16,IF(P16="vrp_50",J16,M16)) -> 3.7709935 | V16: =L16-O16 -> 0
A17: A | B17: A-n53-k7 | C17: 52 | D17: =Data!J47 -> 1010 | E17: =Data!B48 -> 1023.7313 | F17: =IF(E17="","",IFERROR(E17/D17-1,"")) -> 0.013595309 | G17: =Data!D48 -> 3.8916929 | H17: =Data!B49 -> 1091.8982 | I17: =IF(H17="","",IFERROR(H17/D17-1,"")) -> 0.08108732 | J17: =Data!D49 -> 3.5289092 | K17: =Data!B47 -> 1076.1646 | L17: =IF(K17="","",IFERROR(K17/D17-1,"")) -> 0.065509456 | M17: =Data!D47 -> 3.9444933 | N17: =MIN(E17,H17,K17) -> 1023.7313 | O17: =MIN(F17,I17,L17) -> 0.013595309 | P17: =IF(N17=E17,"vrp_20",IF(N17=H17,"vrp_50","vrp_100")) -> vrp_20 | Q17: =SUM(G17,J17,M17) -> 11.365095 | R17: =IF(C17<=50,"≤50",IF(C17<=100,"51-100",IF(C17<=200,"101-200",IF(C17<=500,"201-500",">500")))) -> 51-100 | S17: =IF(O17<=0,"≤0%",IF(O17<=0.01,"0-1%",IF(O17<=0.02,"1-2%",IF(O17<=0.05,"2-5%",IF(O17<=0.1,"5-10%",">10%"))))) -> 1-2% | T17: =IF(O17<0,"VERIFICAR: gap < 0",IF(O17>0.2,"ATENÇÃO: gap > 20%","")) | U17: =IF(P17="vrp_20",G17,IF(P17="vrp_50",J17,M17)) -> 3.8916929 | V17: =L17-O17 -> 0.051914147
A18: A | B18: A-n54-k7 | C18: 53 | D18: =Data!J50 -> 1167 | E18: =Data!B51 -> 1219.5427 | F18: =IF(E18="","",IFERROR(E18/D18-1,"")) -> 0.045023757 | G18: =Data!D51 -> 3.784946 | H18: =Data!B52 -> 1173.3167 | I18: =IF(H18="","",IFERROR(H18/D18-1,"")) -> 0.0054127253 | J18: =Data!D52 -> 3.5621855 | K18: =Data!B50 -> 1191.337 | L18: =IF(K18="","",IFERROR(K18/D18-1,"")) -> 0.020854358 | M18: =Data!D50 -> 3.8616569 | N18: =MIN(E18,H18,K18) -> 1173.3167 | O18: =MIN(F18,I18,L18) -> 0.0054127253 | P18: =IF(N18=E18,"vrp_20",IF(N18=H18,"vrp_50","vrp_100")) -> vrp_50 | Q18: =SUM(G18,J18,M18) -> 11.208788 | R18: =IF(C18<=50,"≤50",IF(C18<=100,"51-100",IF(C18<=200,"101-200",IF(C18<=500,"201-500",">500")))) -> 51-100 | S18: =IF(O18<=0,"≤0%",IF(O18<=0.01,"0-1%",IF(O18<=0.02,"1-2%",IF(O18<=0.05,"2-5%",IF(O18<=0.1,"5-10%",">10%"))))) -> 0-1% | T18: =IF(O18<0,"VERIFICAR: gap < 0",IF(O18>0.2,"ATENÇÃO: gap > 20%","")) | U18: =IF(P18="vrp_20",G18,IF(P18="vrp_50",J18,M18)) -> 3.5621855 | V18: =L18-O18 -> 0.015441633
A19: A | B19: A-n55-k9 | C19: 54 | D19: =Data!J53 -> 1073 | E19: =Data!B54 -> 1146.5979 | F19: =IF(E19="","",IFERROR(E19/D19-1,"")) -> 0.068590774 | G19: =Data!D54 -> 4.8907831 | H19: =Data!B55 -> 1092.6515 | I19: =IF(H19="","",IFERROR(H19/D19-1,"")) -> 0.018314529 | J19: =Data!D55 -> 3.5954039 | K19: =Data!B53 -> 1145.2159 | L19: =IF(K19="","",IFERROR(K19/D19-1,"")) -> 0.067302835 | M19: =Data!D53 -> 3.9414515 | N19: =MIN(E19,H19,K19) -> 1092.6515 | O19: =MIN(F19,I19,L19) -> 0.018314529 | P19: =IF(N19=E19,"vrp_20",IF(N19=H19,"vrp_50","vrp_100")) -> vrp_50 | Q19: =SUM(G19,J19,M19) -> 12.427639 | R19: =IF(C19<=50,"≤50",IF(C19<=100,"51-100",IF(C19<=200,"101-200",IF(C19<=500,"201-500",">500")))) -> 51-100 | S19: =IF(O19<=0,"≤0%",IF(O19<=0.01,"0-1%",IF(O19<=0.02,"1-2%",IF(O19<=0.05,"2-5%",IF(O19<=0.1,"5-10%",">10%"))))) -> 1-2% | T19: =IF(O19<0,"VERIFICAR: gap < 0",IF(O19>0.2,"ATENÇÃO: gap > 20%","")) | U19: =IF(P19="vrp_20",G19,IF(P19="vrp_50",J19,M19)) -> 3.5954039 | V19: =L19-O19 -> 0.048988307
A20: A | B20: A-n60-k9 | C20: 59 | D20: =Data!J56 -> 1354 | E20: =Data!B57 -> 1410.3086 | F20: =IF(E20="","",IFERROR(E20/D20-1,"")) -> 0.041586849 | G20: =Data!D57 -> 3.8256223 | H20: =Data!B58 -> 1385.636 | I20: =IF(H20="","",IFERROR(H20/D20-1,"")) -> 0.023364835 | J20: =Data!D58 -> 3.4479377 | K20: =Data!B56 -> 1379.5469 | L20: =IF(K20="","",IFERROR(K20/D20-1,"")) -> 0.018867707 | M20: =Data!D56 -> 3.9028752 | N20: =MIN(E20,H20,K20) -> 1379.5469 | O20: =MIN(F20,I20,L20) -> 0.018867707 | P20: =IF(N20=E20,"vrp_20",IF(N20=H20,"vrp_50","vrp_100")) -> vrp_100 | Q20: =SUM(G20,J20,M20) -> 11.176435 | R20: =IF(C20<=50,"≤50",IF(C20<=100,"51-100",IF(C20<=200,"101-200",IF(C20<=500,"201-500",">500")))) -> 51-100 | S20: =IF(O20<=0,"≤0%",IF(O20<=0.01,"0-1%",IF(O20<=0.02,"1-2%",IF(O20<=0.05,"2-5%",IF(O20<=0.1,"5-10%",">10%"))))) -> 1-2% | T20: =IF(O20<0,"VERIFICAR: gap < 0",IF(O20>0.2,"ATENÇÃO: gap > 20%","")) | U20: =IF(P20="vrp_20",G20,IF(P20="vrp_50",J20,M20)) -> 3.9028752 | V20: =L20-O20 -> 0
A21: A | B21: A-n61-k9 | C21: 60 | D21: =Data!J59 -> 1034 | E21: =Data!B60 -> 1073.7109 | F21: =IF(E21="","",IFERROR(E21/D21-1,"")) -> 0.038405162 | G21: =Data!D60 -> 3.8462729 | H21: =Data!B61 -> 1074.1986 | I21: =IF(H21="","",IFERROR(H21/D21-1,"")) -> 0.038876797 | J21: =Data!D61 -> 4.1932976 | K21: =Data!B59 -> 1088.1638 | L21: =IF(K21="","",IFERROR(K21/D21-1,"")) -> 0.052382803 | M21: =Data!D59 -> 3.369669 | N21: =MIN(E21,H21,K21) -> 1073.7109 | O21: =MIN(F21,I21,L21) -> 0.038405162 | P21: =IF(N21=E21,"vrp_20",IF(N21=H21,"vrp_50","vrp_100")) -> vrp_20 | Q21: =SUM(G21,J21,M21) -> 11.40924 | R21: =IF(C21<=50,"≤50",IF(C21<=100,"51-100",IF(C21<=200,"101-200",IF(C21<=500,"201-500",">500")))) -> 51-100 | S21: =IF(O21<=0,"≤0%",IF(O21<=0.01,"0-1%",IF(O21<=0.02,"1-2%",IF(O21<=0.05,"2-5%",IF(O21<=0.1,"5-10%",">10%"))))) -> 2-5% | T21: =IF(O21<0,"VERIFICAR: gap < 0",IF(O21>0.2,"ATENÇÃO: gap > 20%","")) | U21: =IF(P21="vrp_20",G21,IF(P21="vrp_50",J21,M21)) -> 3.8462729 | V21: =L21-O21 -> 0.013977641
A22: A | B22: A-n62-k8 | C22: 61 | D22: =Data!J62 -> 1288 | E22: =Data!B63 -> 1364.3846 | F22: =IF(E22="","",IFERROR(E22/D22-1,"")) -> 0.059304847 | G22: =Data!D63 -> 4.0444791 | H22: =Data!B64 -> 1328.6812 | I22: =IF(H22="","",IFERROR(H22/D22-1,"")) -> 0.031584746 | J22: =Data!D64 -> 3.1809607 | K22: =Data!B62 -> 1337.7933 | L22: =IF(K22="","",IFERROR(K22/D22-1,"")) -> 0.038659422 | M22: =Data!D62 -> 3.1158252 | N22: =MIN(E22,H22,K22) -> 1328.6812 | O22: =MIN(F22,I22,L22) -> 0.031584746 | P22: =IF(N22=E22,"vrp_20",IF(N22=H22,"vrp_50","vrp_100")) -> vrp_50 | Q22: =SUM(G22,J22,M22) -> 10.341265 | R22: =IF(C22<=50,"≤50",IF(C22<=100,"51-100",IF(C22<=200,"101-200",IF(C22<=500,"201-500",">500")))) -> 51-100 | S22: =IF(O22<=0,"≤0%",IF(O22<=0.01,"0-1%",IF(O22<=0.02,"1-2%",IF(O22<=0.05,"2-5%",IF(O22<=0.1,"5-10%",">10%"))))) -> 2-5% | T22: =IF(O22<0,"VERIFICAR: gap < 0",IF(O22>0.2,"ATENÇÃO: gap > 20%","")) | U22: =IF(P22="vrp_20",G22,IF(P22="vrp_50",J22,M22)) -> 3.1809607 | V22: =L22-O22 -> 0.0070746759
A23: A | B23: A-n63-k10 | C23: 62 | D23: =Data!J66 -> 1314 | E23: =Data!B68 -> 1354.1973 | F23: =IF(E23="","",IFERROR(E23/D23-1,"")) -> 0.030591526 | G23: =Data!D68 -> 6.9907918 | H23: =Data!B70 -> 1358.572 | I23: =IF(H23="","",IFERROR(H23/D23-1,"")) -> 0.033920869 | J23: =Data!D70 -> 6.727206 | K23: =Data!B66 -> 1343.3353 | L23: =IF(K23="","",IFERROR(K23/D23-1,"")) -> 0.022325211 | M23: =Data!D66 -> 5.4418101 | N23: =MIN(E23,H23,K23) -> 1343.3353 | O23: =MIN(F23,I23,L23) -> 0.022325211 | P23: =IF(N23=E23,"vrp_20",IF(N23=H23,"vrp_50","vrp_100")) -> vrp_100 | Q23: =SUM(G23,J23,M23) -> 19.159808 | R23: =IF(C23<=50,"≤50",IF(C23<=100,"51-100",IF(C23<=200,"101-200",IF(C23<=500,"201-500",">500")))) -> 51-100 | S23: =IF(O23<=0,"≤0%",IF(O23<=0.01,"0-1%",IF(O23<=0.02,"1-2%",IF(O23<=0.05,"2-5%",IF(O23<=0.1,"5-10%",">10%"))))) -> 2-5% | T23: =IF(O23<0,"VERIFICAR: gap < 0",IF(O23>0.2,"ATENÇÃO: gap > 20%","")) | U23: =IF(P23="vrp_20",G23,IF(P23="vrp_50",J23,M23)) -> 5.4418101 | V23: =L23-O23 -> 0
